Workbook

Sheet README
A1: FIRE 統合要件書 v3.1 — 全開発TODO管理表
A3: 作成日 | B3: 2026-04-21
A4: 対象要件書 | B4: FIRE 統合要件書 v3.1（製本版）
A5: 開発環境 | B5: 初期: Windows PC(全ロジック開発) / Mac mini M4 Pro 到着後: 常駐運用基盤へ移行
A6: 管理方針 | B6: Git + Obsidian + .md で開発進捗を可視化、タスク完了時に必ずクローズ
A8: ■ シート構成
A9: README | B9: 本シート（凡例・使い方）
A10: TODO_Master | B10: 全開発タスク一覧（メインシート）
A11: Phase_Summary | B11: フェーズ別サマリー（進捗集計）
A12: Agent_Checklist | B12: 10エージェント別の実装チェックリスト
A13: Stage_Gate | B13: Stage 0→4 昇格ゲートチェックリスト
A14: Roadmap | B14: M-3 〜 M+3 立ち上げロードマップ
A15: Risk_Holes | B15: 穴1〜11（要件書で特定された落とし穴）対策チェック
A17: ■ ステータス定義
A18: 未着手 | B18: まだ着手していない
A19: 設計中 | B19: 設計・検討フェーズ
A20: 実装中 | B20: コード実装中
A21: 検証中 | B21: テスト・Simulation検証中
A22: レビュー待ち | B22: ユーザー承認待ち
A23: 完了 | B23: タスククローズ済み
A24: 凍結 | B24: 一時保留
A26: ■ 優先度定義
A27: 最優先 | B27: これが無いと次に進めない（Pattern Store、Runtime骨組み等）
A28: 高 | B28: 主戦略・本番運用に必須
A29: 中 | B29: 運用品質向上に必要
A30: 低 | B30: 後回し可（後から拡張）
A32: ■ 開発着手順の最重要前提（要件書15章・23章より）
A33: 1 | B33: Pattern Store / Feature Store / Runtime / Simulation の骨組みを最優先で作成
A34: 2 | B34: リアルタイム Paper Live 環境 + LINE通知基盤を構築
A35: 3 | B35: 実弾執行基盤（証券API連携）は後回しで着手
A36: 4 | B36: 各エージェントのプロンプトファイルを整備
A38: ■ 使い方
A39: 1 | B39: TODO_Master シートで各タスクのステータスを更新
A40: 2 | B40: 完了したらステータスを「完了」に変更し、完了日を入力
A41: 3 | B41: Phase_Summary で進捗を自動集計（SUMIFS/COUNTIFS）
A42: 4 | B42: GitとObsidianに対応する.mdファイルを必ず作成し、本表のタスクIDを記載
A45: ■ 要件トレーサビリティマトリクス (RTM)
A46: RTM_要件カバレッジ | B46: 要件書全要件を要件ID(R-章-連番)で採番し、対応タスクIDを紐付け。赤=未カバー、黄=1件紐付け、緑=2件以上
A47: RTM_章別サマリー | B47: 章別の要件数・カバー済・未カバー・カバレッジ率を自動集計。未カバーが1件でもある章を黄色ハイライト
A49: ■ 要件抜け漏れ確認の正式な場所
...

Sheet TODO_Master
A1: ID | B1: フェーズ | C1: カテゴリ | D1: 要件書章 | E1: タスク名 | F1: 詳細 | G1: 優先度 | H1: 依存 | I1: 担当 | J1: 想定工数(日) | K1: ステータス | L1: 着手日 | M1: 完了日 | N1: 成果物 | O1: 備考
A2: F001 | B2: P0: 基盤・環境構築 | C2: 移行準備 | D2: - | E2: Windows資産のZIP化・クラウドアップロード(Mac到着前) | F2: Windows PCで fire-vault をZIP化し、Google Drive等にアップロード。FIRE_開発TODO_v7.xlsx、要件書PDF原本、引き継ぎコンテキスト.md も一緒にアップ。Mac mini到着時に即ダウンロードできる状態にする。 | G2: 最優先 | I2: Fujiwara | J2: 0.2 | K2: 完了 | N2: Google Drive上のfire-vault_backup.zip + 関連ファイル一式 | O2: Mac mini到着前に完了させておく。Windows_to_Mac_移行手順.md 参照
A3: F019 | B3: P0: 基盤・環境構築 | C3: アカウント | D3: - | E3: Claude 個人アカウント契約(Pro or Max) | F3: FIRE開発専用のClaude個人アカウントを契約(StudioZ業務用とは分離)。推奨はClaude Pro($20/月)またはMaxプラン。Claude Code利用のため2FA必須。契約後、新アカウントで引き継ぎコンテキスト.mdを投入してFIRE開発を継続。 | G3: 最優先 | H3: F001 | I3: Fujiwara | J3: 0.2 | K3: 完了 | N3: 新Claudeアカウント(個人用・Pro/Max契約済み) | O3: Claude Code の長時間実行・大容量コンテキストに対応するため有料プラン推奨
A4: F002 | B4: P0: 基盤・環境構築 | C4: 環境 | D4: 16 | E4: Mac mini M4 Pro 受領・初期設定 | F4: システム設定: スリープしない/自動再起動/自動ログイン/ファイアウォール/画面共有/SSH/Tailscale。要件書16章。 | G4: 最優先 | H4: F019 | I4: Fujiwara | J4: Fujiwara | K4: 完了 | N4: Mac mini運用環境 | O4: Claude個人アカウント契約(F019)完了後、Mac受領時に着手
A5: F003 | B5: P0: 基盤・環境構築 | C5: 環境 | D5: 16 | E5: Mac mini 開発環境セットアップ | F5: Homebrew / Python@3.12 / Node.js LTS / Git / Obsidian / VS Code + 拡張をbrewとApp Storeで一括導入。.zshrc に環境変数設定。 | G5: 最優先 | H5: F002 | I5: Fujiwara | J5: Fujiwara | K5: 完了 | N5: Mac環境 | O5: Windows で決めたツール構成をMac版で再現
A6: F016 | B6: P0: 基盤・環境構築 | C6: 移行 | D6: - | E6: Windows資産のMac mini移行 | F6: Obsidian Vault(fire-vault)/要件書39章.md/タスク運用ルール.md/Google Sheetsリンクを iCloud・Dropbox・GitHub経由でMacに展開。GitHub(BlueFire7777)の鍵登録。 | G6: 最優先 | H6: F001,F003 | I6: 両方 | J6: Fujiwara | K6: 完了 | N6: docs/migration_to_mac.md | O6: Windows側で作成したZIP(F001)を Mac に展開。F003 の Mac 開発環境セットアップ完了後
A7: F017 | B7: P0: 基盤・環境構築 | C7: ドキュメント | D7: - | E7: Claudeアカウント引き継ぎ・新ランタイム確認 | F7: 新Claude個人アカウント(F019)でFIREプロジェクトコンテキストを引き継ぎ、CLAUDE.mdと要件書を認識させる。Windows資産(F016)がMac上で使える状態で動作確認。 | G7: 最優先 | H7: F019,F016 | I7: Fujiwara | J7: 0.5 | K7: 完了 | N7: 新アカウントでのclaude動作確認 | O7: 新Claudeアカウントでの継続運用の起点
A8: F018 | B8: P0: 基盤・環境構築 | C8: 環境 | D8: 16 | E8: Mac .zshrc プロファイル設定 | F8: $FIRE_HOME / $FIRE_VAULT / $CLAUDE_CODE_EFFORT_LEVEL / $FIRE_PLATFORM=mac 等の環境変数と、fire / firevault / py312 等のエイリアス・関数を.zshrcに設定。 | G8: 最優先 | H8: F003 | I8: Fujiwara | J8: 0.3 | K8: 完了 | N8: ~/.zshrc | O8: Windows PowerShellプロファイルのMac版
A9: F235 | B9: P0: 基盤・環境構築 | C9: 証券会社設定 | D9: 14 | E9: 楽天証券 約定通知メール設定 | F9: 楽天証券ログイン → 設定・変更 → お知らせメール設定 → 注文約定通知 ON。M+2 以降に Gmail API で自動取込するための前提設定。Fujiwara さん自身の作業。 | G9: 最優先 | I9: Fujiwara | J9: 0.1 | K9: 完了 | N9: 楽天証券の約定通知メール配信設定 | O9: v3.3 新規。M+2 以降の Gmail API 自動取込の前提
A10: F242 | B10: P0: 基盤・環境構築 | C10: 基盤 | D10: 23 | E10: OpenClaw セットアップ(Mac mini 常駐基盤) | F10: Mac mini M4 Pro に OpenClaw をインストールし、常駐・スケジュール・並列実行・自動復旧・セッション永続化の基盤を確立。ハートビートと再起動テスト。Anthropic API キー設定。 | G10: 最優先 | H10: F003 | I10: Claude | J10: 3 | K10: 完了 | N10: OpenClaw on Mac mini 稼働状態 | O10: v3.3 の核心。FIRE 専用ランナー自作を廃止して OpenClaw 採用
A11: F004 | B11: P0: 基盤・環境構築 | C11: リポジトリ | D11: 15 | E11: Gitリポジトリ初期化 | F11: fireリポジトリ作成、README.md/CLAUDE.md/.gitignore/requirements.txt/package.json作成。ブランチ戦略(main/dev/feature)定義。 | G11: 最優先 | H11: F001 | I11: 両方 | J11: 0.5 | K11: 完了 | N11: github.com/xxx/fire
A12: F005 | B12: P0: 基盤・環境構築 | C12: ドキュメント | D12: 15 | E12: CLAUDE.md 初稿作成 | F12: Claude Codeへの実装指示書。要件書の決定事項を削らず記載。崩してはならない前提リスト。 | G12: 最優先 | H12: F004 | I12: Claude | J12: 0.5 | K12: 完了 | N12: CLAUDE.md
A13: F006 | B13: P0: 基盤・環境構築 | C13: ドキュメント | D13: 15 | E13: README.md 初稿作成 | F13: プロジェクト概要、セットアップ手順、ディレクトリ構造、開発フロー記載。 | G13: 最優先 | H13: F004 | I13: Claude | J13: 0.5 | K13: 完了 | N13: README.md
A14: F007 | B14: P0: 基盤・環境構築 | C14: ドキュメント | D14: - | E14: Obsidian Vault 構築 | F14: 開発ログ/設計メモ/日次レビュー用のVault作成。docs/配下と連携。タスクIDリンク運用。 | G14: 最優先 | H14: F004 | I14: Fujiwara | J14: 0.5 | K14: 完了 | N14: Obsidian Vault
A15: F008 | B15: P0: 基盤・環境構築 | C15: ディレクトリ | D15: - | E15: プロジェクトディレクトリ構造設計 | F15: agents/ runtime/ patterns/ features/ simulation/ dashboard/ notifications/ broker/ data/ logs/ docs/ tests/ scripts/ | G15: 最優先 | H15: F004 | I15: Claude | J15: 0.5 | K15: 完了 | N15: ディレクトリ構造
A16: F011 | B16: P0: 基盤・環境構築 | C16: DB | D16: - | E16: ローカルDB選定・初期化 | F16: Pattern/Feature/Live Research Log用。SQLite or DuckDB or PostgreSQL選定。スキーマ設計。 | G16: 最優先 | H16: F008 | I16: Claude | J16: 1 | K16: 完了 | N16: db/schema.sql
A17: F012 | B17: P0: 基盤・環境構築 | C17: スケジューラ | D17: 23 | E17: FIRE Runner骨組み | F17: メインオーケストレーター。エージェント起動/停止/スケジュール管理。時間帯別処理起動。Windows/Mac両対応で実装。 | G17: 最優先 | H17: F010 | I17: Claude | J17: 2 | K17: 完了 | N17: runtime/main.py | O17: OS非依存で実装。launchd固有部分はF013で追加
A18: F013 | B18: P0: 基盤・環境構築 | C18: launchd | D18: 16 | E18: Mac mini launchd常駐自動起動設定 | F18: ~/Library/LaunchAgents/com.fire.runtime.plist作成、launchctl load、動作確認。FIRE Runtime常駐基盤の完成。 | G18: 最優先 | H18: F003,F012 | I18: Fujiwara | J18: Fujiwara | K18: 完了 | N18: com.fire.runtime.plist | O18: 要件書16章。常駐化により以降のPaper Live本格稼働が可能に
A19: F009 | B19: P0: 基盤・環境構築 | C19: 設定 | D19: 16 | E19: 環境変数管理基盤 | F19: .env設計、RAKUTEN_API_KEY/LINE_CHANNEL_TOKEN/NEWS_API_KEY/TDNET_API_KEY等。.env.example整備。秘匿情報のgit除外。 | G19: 高 | H19: F004 | I19: Claude | J19: 0.5 | K19: 完了 | N19: .env, .env.example
A20: F010 | B20: P0: 基盤・環境構築 | C20: ロギング | D20: - | E20: 共通ロギング基盤 | F20: logs/配下に構造化ログ(JSON)。レベル分け、ローテーション、監査用の永続化。 | G20: 高 | H20: F008 | I20: Claude | J20: 1 | K20: 完了 | N20: utils/logger.py
A21: F020 | B21: P1: Pattern/Feature Store | C21: データ基盤 | D21: 21,36 | E21: Feature Store スキーマ設計 | F21: 6系統特徴量(材料/地合い/出来高/値動き/執行品質/時間帯)の全カラム定義。時系列/スナップショット管理。 | G21: 最優先 | H21: F011 | I21: Claude | J21: 2 | K21: 完了 | N21: features/schema.md
A22: F027 | B22: P1: Pattern/Feature Store | C22: Store | D22: 11,21,37 | E22: Pattern Store 4階層構造実装 | F22: Layer1: Pattern Archive / Layer2: Valid Library / Layer3: Active Priority Set / Layer4: Death Note・Rehab。 | G22: 最優先 | H22: F011,F020 | I22: Claude | J22: 3 | K22: 完了 | N22: patterns/store.py
A23: F028 | B23: P1: Pattern/Feature Store | C23: Store | D23: 21,37 | E23: パターン7状態管理 | F23: candidate/paper_validating/approved_active/watchlist/frozen/death_note/rehab の遷移ルール実装。 | G23: 最優先 | H23: F027 | I23: Claude | J23: 1.5 | K23: 完了 | N23: patterns/state_machine.py
A24: F031 | B24: P1: Pattern/Feature Store | C24: 検索 | D24: 11,21,26 | E24: 類似局面検索エンジン | F24: Feature Storeから現在局面と過去局面の類似度計算。重み付け(材料30/地合い20/流動性20/値動き20/執行10)。 | G24: 最優先 | H24: F020,F027 | I24: Claude | J24: 3 | K24: 完了 | N24: patterns/similarity.py
A25: F032 | B25: P1: Pattern/Feature Store | C25: スコアリング | D25: 11,26 | E25: 再現性スコア合成エンジン | F25: 類似度+類似件数+勝率+平均RR+期待値+レジーム適合+直近有効性+執行品質+リスク管理適合 の合成。 | G25: 最優先 | H25: F031 | I25: Claude | J25: 2 | K25: 完了 | N25: patterns/repro_score.py
A26: F180 | B26: P1: Pattern/Feature Store | C26: ラベル | D26: 29 | E26: 成功/失敗ラベル4分類 | F26: Success/Failure/Timeout/Invalid。target_holding_window内で損切より先に利確1到達=Success。 | G26: 最優先 | H26: F020 | I26: Claude | J26: 1.5 | K26: 完了 | N26: labels/classifier.py
A27: F200 | B27: P1: Pattern/Feature Store | C27: 戦略 | D27: 3,25 | E27: 3レーン戦略構造 | F27: Primary(材料初動80%+主役テーマ値嵩)/Secondary(押し目再加速等 20%/M+2までPaper並走)/Research(準スキャル等)。 | G27: 最優先 | H27: F111 | I27: Claude | J27: 2 | K27: 完了 | N27: strategies/lanes.py
A28: F021 | B28: P1: Pattern/Feature Store | C28: データ取得 | D28: 36 | E28: 材料特徴量収集エンジン | F28: material_type/freshness/strength_score/multi_material_flag/earnings_related_flag/shareholder_return_flag。 | G28: 高 | H28: F020 | I28: Claude | J28: 2 | K28: 完了 | N28: features/material.py | O28: TDnet/IR/NewsAPI連携は後続
A29: F022 | B29: P1: Pattern/Feature Store | C29: データ取得 | D29: 36 | E29: 地合い特徴量収集エンジン | F29: nikkei/topix_direction、sector_strength_rank、theme_strength_rank、market_regime分類、usd_jpy、overnight_us。 | G29: 高 | H29: F020 | I29: Claude | J29: 2 | K29: 完了 | N29: features/regime.py
A30: F023 | B30: P1: Pattern/Feature Store | C30: データ取得 | D30: 36 | E30: 出来高/流動性特徴量エンジン | F30: volume_ratio/turnover/liquidity_score/spread_estimate/high_price_stock_flag/board_thickness_score。 | G30: 高 | H30: F020 | I30: Claude | J30: 1.5 | K30: 完了 | N30: features/liquidity.py
A31: F024 | B31: P1: Pattern/Feature Store | C31: データ取得 | D31: 36 | E31: 値動き/テクニカル特徴量エンジン | F31: gap_pct/intraday_range/breakout/pullback/vwap_position/ma_alignment/RS/price_action_pattern/S&R距離。 | G31: 高 | H31: F020 | I31: Claude | J31: 2 | K31: 完了 | N31: features/technical.py
A32: F025 | B32: P1: Pattern/Feature Store | C32: データ取得 | D32: 36 | E32: 執行品質特徴量エンジン | F32: entry/stop_slippage_estimate、partial_fill_risk、fill_quality_score、forced_close_risk_score。 | G32: 高 | H32: F020 | I32: Claude | J32: 1.5 | K32: 完了 | N32: features/execution.py
A33: F026 | B33: P1: Pattern/Feature Store | C33: データ取得 | D33: 36 | E33: 時間帯特徴量エンジン | F33: session_phase/minutes_from_open/minutes_to_force_close/material_to_entry_lag_minutes。 | G33: 高 | H33: F020 | I33: Claude | J33: 1 | K33: 完了 | N33: features/time.py
A34: F029 | B34: P1: Pattern/Feature Store | C34: Store | D34: 37 | E34: パターン格付け(S〜X)実装 | F34: S/A/B/C/D/X のランク付けと自動判定ロジック。再現性スコア/期待値/類似件数ベース。 | G34: 高 | H34: F028 | I34: Claude | J34: 1 | K34: 完了 | N34: patterns/ranking.py
A35: F030 | B35: P1: Pattern/Feature Store | C35: Store | D35: 21,31,37 | E35: pattern_id / 命名規則 / バージョン管理 | F35: [material]-[regime]-[price_action]-[time]-[liquidity] 形式。parent_pattern_id、change_reason必須。 | G35: 高 | H35: F027 | I35: Claude | J35: 1 | K35: 完了 | N35: patterns/naming.py
A36: F033 | B36: P1: Pattern/Feature Store | C36: DEATH NOTE | D36: 21 | E36: DEATH NOTE 3段階判定 | F36: Step1(5回で4敗)→要警戒 / Step2(10回勝率30%未満)→凍結候補 / Step3(20回期待値マイナス)→DEATH NOTE。 | G36: 高 | H36: F028 | I36: Claude | J36: 1 | K36: 完了 | N36: patterns/death_note.py | O36: 単純連敗即死禁止
A37: F035 | B37: P1: Pattern/Feature Store | C37: Agent | D37: 21 | E37: Pattern Research Agent | F37: パターン研究責任者。過去/リアルタイムからの発見・定義・更新提案。自動反映禁止。 | G37: 高 | H37: F031,F032 | I37: Claude | J37: 3 | K37: 完了 | N37: agents/pattern_research.py
A38: F036 | B38: P1: Pattern/Feature Store | C38: ログ | D38: 21 | E38: Live Research Log 実装 | F38: リアルタイム観測ログ。候補/類似パターン/実成績/最大含み益/最大逆行/約定品質/地合い保存。 | G38: 高 | H38: F035 | I38: Claude | J38: 1.5 | K38: 完了 | N38: patterns/live_log.py
A39: F038 | B39: P1: Pattern/Feature Store | C39: 承認フロー | D39: 21 | E39: パターン採用承認フロー | F39: candidate→Paper/Sim検証→Evaluation評価→ユーザー承認→Library登録。凍結/DN/REHABも承認制。 | G39: 高 | H39: F035 | I39: Claude | J39: 1 | K39: 未着手 | N39: patterns/approval.py
A40: F181 | B40: P1: Pattern/Feature Store | C40: ラベル | D40: 29 | E40: target_holding_window パターン別管理 | F40: 材料初動10-30分/主役テーマ15-45分/準スキャル3-10分。 | G40: 高 | H40: F180 | I40: Claude | J40: 0.5 | K40: 未着手 | N40: labels/windows.py
...

Sheet Phase_Summary
A1: FIRE 開発 — フェーズ別進捗サマリー
A3: フェーズ | B3: 総タスク数 | C3: 完了 | D3: 実装中+検証中 | E3: 未着手 | F3: 完了率
A4: P0: 基盤・環境構築 | B4: =COUNTIF(TODO_Master!B2:B126,A4) -> 19 | C4: =COUNTIFS(TODO_Master!B2:B126,A4,TODO_Master!K2:K126,"完了") -> 19 | D4: =COUNTIFS(TODO_Master!B2:B126,A4,TODO_Master!K2:K126,"実装中")+COUNTIFS(TODO_Master!B2:B126,A4,TODO_Master!K2:K126,"検証中")+COUNTIFS(TODO_Master!B2:B126,A4,TODO_Master!K2:K126,"設計中") -> 0 | E4: =COUNTIFS(TODO_Master!B2:B126,A4,TODO_Master!K2:K126,"未着手") -> 0 | F4: =IFERROR(C4/B4,0) -> 1
A5: P1: Pattern/Feature Store | B5: =COUNTIF(TODO_Master!B2:B126,A5) -> 26 | C5: =COUNTIFS(TODO_Master!B2:B126,A5,TODO_Master!K2:K126,"完了") -> 18 | D5: =COUNTIFS(TODO_Master!B2:B126,A5,TODO_Master!K2:K126,"実装中")+COUNTIFS(TODO_Master!B2:B126,A5,TODO_Master!K2:K126,"検証中")+COUNTIFS(TODO_Master!B2:B126,A5,TODO_Master!K2:K126,"設計中") -> 0 | E5: =COUNTIFS(TODO_Master!B2:B126,A5,TODO_Master!K2:K126,"未着手") -> 8 | F5: =IFERROR(C5/B5,0) -> 0.69230769
A6: P2: Simulation/Backtest | B6: =COUNTIF(TODO_Master!B2:B126,A6) -> 8 | C6: =COUNTIFS(TODO_Master!B2:B126,A6,TODO_Master!K2:K126,"完了") -> 0 | D6: =COUNTIFS(TODO_Master!B2:B126,A6,TODO_Master!K2:K126,"実装中")+COUNTIFS(TODO_Master!B2:B126,A6,TODO_Master!K2:K126,"検証中")+COUNTIFS(TODO_Master!B2:B126,A6,TODO_Master!K2:K126,"設計中") -> 0 | E6: =COUNTIFS(TODO_Master!B2:B126,A6,TODO_Master!K2:K126,"未着手") -> 8 | F6: =IFERROR(C6/B6,0) -> 0
A7: P3: Paper Live | B7: =COUNTIF(TODO_Master!B2:B126,A7) -> 4 | C7: =COUNTIFS(TODO_Master!B2:B126,A7,TODO_Master!K2:K126,"完了") -> 0 | D7: =COUNTIFS(TODO_Master!B2:B126,A7,TODO_Master!K2:K126,"実装中")+COUNTIFS(TODO_Master!B2:B126,A7,TODO_Master!K2:K126,"検証中")+COUNTIFS(TODO_Master!B2:B126,A7,TODO_Master!K2:K126,"設計中") -> 0 | E7: =COUNTIFS(TODO_Master!B2:B126,A7,TODO_Master!K2:K126,"未着手") -> 4 | F7: =IFERROR(C7/B7,0) -> 0
A8: P4: LINE/通知基盤 | B8: =COUNTIF(TODO_Master!B2:B126,A8) -> 35 | C8: =COUNTIFS(TODO_Master!B2:B126,A8,TODO_Master!K2:K126,"完了") -> 0 | D8: =COUNTIFS(TODO_Master!B2:B126,A8,TODO_Master!K2:K126,"実装中")+COUNTIFS(TODO_Master!B2:B126,A8,TODO_Master!K2:K126,"検証中")+COUNTIFS(TODO_Master!B2:B126,A8,TODO_Master!K2:K126,"設計中") -> 0 | E8: =COUNTIFS(TODO_Master!B2:B126,A8,TODO_Master!K2:K126,"未着手") -> 35 | F8: =IFERROR(C8/B8,0) -> 0
A9: P5: Dashboard | B9: =COUNTIF(TODO_Master!B2:B126,A9) -> 12 | C9: =COUNTIFS(TODO_Master!B2:B126,A9,TODO_Master!K2:K126,"完了") -> 0 | D9: =COUNTIFS(TODO_Master!B2:B126,A9,TODO_Master!K2:K126,"実装中")+COUNTIFS(TODO_Master!B2:B126,A9,TODO_Master!K2:K126,"検証中")+COUNTIFS(TODO_Master!B2:B126,A9,TODO_Master!K2:K126,"設計中") -> 0 | E9: =COUNTIFS(TODO_Master!B2:B126,A9,TODO_Master!K2:K126,"未着手") -> 12 | F9: =IFERROR(C9/B9,0) -> 0
A10: P6: 証券API連携 | B10: =COUNTIF(TODO_Master!B2:B126,A10) -> 8 | C10: =COUNTIFS(TODO_Master!B2:B126,A10,TODO_Master!K2:K126,"完了") -> 0 | D10: =COUNTIFS(TODO_Master!B2:B126,A10,TODO_Master!K2:K126,"実装中")+COUNTIFS(TODO_Master!B2:B126,A10,TODO_Master!K2:K126,"検証中")+COUNTIFS(TODO_Master!B2:B126,A10,TODO_Master!K2:K126,"設計中") -> 0 | E10: =COUNTIFS(TODO_Master!B2:B126,A10,TODO_Master!K2:K126,"未着手") -> 8 | F10: =IFERROR(C10/B10,0) -> 0
A11: P7: Live Advisory | B11: =COUNTIF(TODO_Master!B2:B126,A11) -> 6 | C11: =COUNTIFS(TODO_Master!B2:B126,A11,TODO_Master!K2:K126,"完了") -> 0 | D11: =COUNTIFS(TODO_Master!B2:B126,A11,TODO_Master!K2:K126,"実装中")+COUNTIFS(TODO_Master!B2:B126,A11,TODO_Master!K2:K126,"検証中")+COUNTIFS(TODO_Master!B2:B126,A11,TODO_Master!K2:K126,"設計中") -> 0 | E11: =COUNTIFS(TODO_Master!B2:B126,A11,TODO_Master!K2:K126,"未着手") -> 6 | F11: =IFERROR(C11/B11,0) -> 0
A12: P8: Full Auto(将来) | B12: =COUNTIF(TODO_Master!B2:B126,A12) -> 7 | C12: =COUNTIFS(TODO_Master!B2:B126,A12,TODO_Master!K2:K126,"完了") -> 0 | D12: =COUNTIFS(TODO_Master!B2:B126,A12,TODO_Master!K2:K126,"実装中")+COUNTIFS(TODO_Master!B2:B126,A12,TODO_Master!K2:K126,"検証中")+COUNTIFS(TODO_Master!B2:B126,A12,TODO_Master!K2:K126,"設計中") -> 0 | E12: =COUNTIFS(TODO_Master!B2:B126,A12,TODO_Master!K2:K126,"未着手") -> 7 | F12: =IFERROR(C12/B12,0) -> 0
A13: P9: 運用・保守 | B13: =COUNTIF(TODO_Master!B2:B126,A13) -> 0 | C13: =COUNTIFS(TODO_Master!B2:B126,A13,TODO_Master!K2:K126,"完了") -> 0 | D13: =COUNTIFS(TODO_Master!B2:B126,A13,TODO_Master!K2:K126,"実装中")+COUNTIFS(TODO_Master!B2:B126,A13,TODO_Master!K2:K126,"検証中")+COUNTIFS(TODO_Master!B2:B126,A13,TODO_Master!K2:K126,"設計中") -> 0 | E13: =COUNTIFS(TODO_Master!B2:B126,A13,TODO_Master!K2:K126,"未着手") -> 0 | F13: =IFERROR(C13/B13,0) -> 0
A14: 合計 | B14: =SUM(B4:B13) -> 125 | C14: =SUM(C4:C13) -> 37 | D14: =SUM(D4:D13) -> 0 | E14: =SUM(E4:E13) -> 88 | F14: =IFERROR(C14/B14,0) -> 0.296
A17: 優先度別サマリー
A18: 優先度 | B18: 総タスク数 | C18: 完了 | D18: 実装中+検証中 | E18: 未着手 | F18: 完了率
A19: 最優先 | B19: =COUNTIF(TODO_Master!G2:G126,A19) -> 52 | C19: =COUNTIFS(TODO_Master!G2:G126,A19,TODO_Master!K2:K126,"完了") -> 24 | D19: =COUNTIFS(TODO_Master!G2:G126,A19,TODO_Master!K2:K126,"実装中")+COUNTIFS(TODO_Master!G2:G126,A19,TODO_Master!K2:K126,"検証中")+COUNTIFS(TODO_Master!G2:G126,A19,TODO_Master!K2:K126,"設計中") -> 0 | E19: =COUNTIFS(TODO_Master!G2:G126,A19,TODO_Master!K2:K126,"未着手") -> 28 | F19: =IFERROR(C19/B19,0) -> 0.46153846
A20: 高 | B20: =COUNTIF(TODO_Master!G2:G126,A20) -> 55 | C20: =COUNTIFS(TODO_Master!G2:G126,A20,TODO_Master!K2:K126,"完了") -> 13 | D20: =COUNTIFS(TODO_Master!G2:G126,A20,TODO_Master!K2:K126,"実装中")+COUNTIFS(TODO_Master!G2:G126,A20,TODO_Master!K2:K126,"検証中")+COUNTIFS(TODO_Master!G2:G126,A20,TODO_Master!K2:K126,"設計中") -> 0 | E20: =COUNTIFS(TODO_Master!G2:G126,A20,TODO_Master!K2:K126,"未着手") -> 42 | F20: =IFERROR(C20/B20,0) -> 0.23636364
A21: 中 | B21: =COUNTIF(TODO_Master!G2:G126,A21) -> 11 | C21: =COUNTIFS(TODO_Master!G2:G126,A21,TODO_Master!K2:K126,"完了") -> 0 | D21: =COUNTIFS(TODO_Master!G2:G126,A21,TODO_Master!K2:K126,"実装中")+COUNTIFS(TODO_Master!G2:G126,A21,TODO_Master!K2:K126,"検証中")+COUNTIFS(TODO_Master!G2:G126,A21,TODO_Master!K2:K126,"設計中") -> 0 | E21: =COUNTIFS(TODO_Master!G2:G126,A21,TODO_Master!K2:K126,"未着手") -> 11 | F21: =IFERROR(C21/B21,0) -> 0
A22: 低 | B22: =COUNTIF(TODO_Master!G2:G126,A22) -> 7 | C22: =COUNTIFS(TODO_Master!G2:G126,A22,TODO_Master!K2:K126,"完了") -> 0 | D22: =COUNTIFS(TODO_Master!G2:G126,A22,TODO_Master!K2:K126,"実装中")+COUNTIFS(TODO_Master!G2:G126,A22,TODO_Master!K2:K126,"検証中")+COUNTIFS(TODO_Master!G2:G126,A22,TODO_Master!K2:K126,"設計中") -> 0 | E22: =COUNTIFS(TODO_Master!G2:G126,A22,TODO_Master!K2:K126,"未着手") -> 7 | F22: =IFERROR(C22/B22,0) -> 0

Sheet 開発・運用フェーズ計画
A1: 開発フェーズ(D) と 運用フェーズ(M) の関係
A2: Mac mini 到着待ちの期間を有効活用するための開発・運用フェーズ分離計画
A4: ■ 開発フェーズ (Windows PCで進行可)
A5: Dev Phase | B5: 名称 | C5: 主要タスク | D5: OS依存 | E5: プラットフォーム | F5: Mac mini必要？
A6: D1 | B6: 基盤・環境構築 | C6: F001(Win環境) F004(Gitリポ) F005(CLAUDE.md) F006(README.md) F007(Obsidian) F008(ディレクトリ) F009(.env) F010(ログ) F011(DB) F014(クロスPF設計) | D6: なし | E6: Windows PC | F6: 不要
A7: D2 | B7: Pattern/Feature Store実装 | C7: F020〜F038(Feature Store, Pattern Store 4階層, DEATH NOTE, REHAB, Pattern Research Agent) | D7: なし | E7: Windows PC | F7: 不要
A8: D3 | B8: Simulation/Backtest/Paper Liveロジック | C8: F040〜F053(Backtest, Replay, 3約定モデル, 高速リプレイ並列, Paper Live本体, 仮想管理) | D8: なし(Python計算) | E8: Windows PC | F8: 不要
A9: D4 | B9: エージェント群+LINE通知+Dashboard | C9: F060〜F090(LINE連携, 朝/引けレポート), F110〜F121(10エージェント), F080〜F090(Dashboard) | D9: なし(Python/Node) | E9: Windows PC | F9: 不要
A10: D5 | B10: リスク管理・執行品質・5層防御・ラベル定義 | C10: F130〜F144(リスク/執行ゲート/スリッページ監視), F160〜F164(5層防御), F180〜F183(ラベル) | D10: なし | E10: Windows PC | F10: 不要
A11: D6 | B11: 証券API連携+縮退運転 | C11: F100〜F107(市場データ/TDnet/News/TradingView/楽天API/縮退5段階) | D11: なし(API接続) | E11: Windows PC | F11: 不要
A12: D7 | B12: Windows擬似運用でPaper Live検証 | C12: F015(Winタスクスケジューラ)で日中Paper Live動作確認・不具合洗い出し | D12: Windows固有 | E12: Windows PC | F12: 不要
A13: D8 | B13: Mac mini移行 | C13: F002(Mac初期設定) F003(開発環境) F013(launchd) F016(移行チェック) | D13: Mac固有 | E13: Mac mini | F13: 必須
A16: ■ 運用フェーズ (Mac mini到着後に開始)
A17: Ops Phase | B17: Stage | C17: 実弾 | D17: デイトレリスク | E17: 主要アクション | F17: 前提条件
A18: M-3 〜 M-1 | B18: Stage 0/1/2 | C18: 未投入 | D18: — | E18: Mac mini常時稼働で過去データ高速リプレイ+Paper Live並列実行。パターン爆速蓄積。 | F18: D1-D8完了 / Mac mini常駐化完了
A19: M=0 (運用初月) | B19: Stage 3 Semi Auto | C19: 投入 | D19: 0.2% (半減) | E19: 執行実測データ収集。初月から黒字化目標。 | F19: Paper→Semi昇格基準クリア
A20: M+1 | B20: Stage 3 Semi Auto | C20: 投入 | D20: 0.3% | E20: リスク枠拡大。Pattern Libraryの浄化開始。 | F20: 執行乖離が想定内
A21: M+2 | B21: Stage 3 Semi Auto | C21: 投入 | D21: 0.4% (フルリスク) | E21: フルリスク運用。期待値安定化。 | F21: 継続的な期待値プラス
A22: M+3 以降 | B22: Stage 4 部分Full Auto | C22: 投入 | D22: 0.4% | E22: デイトレSランクのみFull Auto。スイング・長期はSemi Auto維持。 | F22: Semi→Full昇格基準クリア
A25: ■ 重要な考え方
A26: 1. Mac mini到着までの期間は、D1〜D7 の開発作業に最大限使う。コード実装・テスト・Simulation検証までWindows PCで完結可能。
A27: 2. D8 (Mac mini移行) は、Mac mini到着後に短期間で一気に実施。F002→F003→F013→F016の順。
A28: 3. M-3 (運用立ち上げ・パターン爆速蓄積) は、Mac mini常駐化後に正式スタート。Mac到着遅延がM=0を後ろ倒しする。
A29: 4. ただしWindows PC上でもD7(擬似Paper Live検証)でPattern Storeの仮蓄積は可能。Macに移行した時点で過去データリプレイも高速実行できる。
A30: 5. 要件書15章の「Pattern Store最優先→Paper Live→証券API」の順序は維持。証券API(F104)もWindows PCで実装可能だが、本番実弾はMac miniに移行後。
A31: 6. Mac mini到着が遅れるほど、D1-D7の完成度を上げる時間が増える。これは要件書39章のM-3(爆速蓄積)の期間を実質前倒しすることに相当する。

Sheet Agent_Checklist
A1: FIRE 10エージェント 実装チェックリスト
A3: エージェント名 | B3: 責務 | C3: 関連タスクID | D3: 実装ファイル | E3: ステータス
A4: Market Intelligence Agent | B4: 朝の市況・ニュース・セクター分析、朝レポート生成 | C4: F110, F070 | D4: agents/market_intel.py | E4: 未着手
A5: Daytrade Selection Agent | B5: デイトレ候補抽出・厳選(1〜3銘柄)、スコア付与 | C5: F111, F200 | D5: agents/daytrade_select.py | E5: 未着手
A6: Swing Selection Agent | B6: スイング候補抽出、中期トレンド分析 | C6: F112 | D6: agents/swing_select.py | E6: 未着手
A7: Long-term Selection Agent | B7: 高配当・成長株抽出、長期スコア付与 | C7: F113 | D7: agents/longterm_select.py | E7: 未着手
A8: Portfolio Balance Agent | B8: セクター偏り点検、バランス改善提案 | C8: F114 | D8: agents/portfolio.py | E8: 未着手
A9: Trade Decision Agent | B9: エントリー/利確/損切/株数提案、リスク計算、注文案生成 | C9: F115, F130 | D9: agents/trade_decision.py | E9: 未着手
A10: Monitoring & Alert Agent | B10: 価格到達監視、LINE通知発火 | C10: F116, F061 | D10: agents/monitoring.py | E10: 未着手
A11: Review & Journal Agent | B11: 引け後レビュー、成績分析、学習データ保存 | C11: F117, F072 | D11: agents/review.py | E11: 未着手
A12: Goal Tracking Agent | B12: 3000万円目標進捗・乖離管理(日週月次) | C12: F118, F210 | D12: agents/goal_tracking.py | E12: 未着手
A13: Evaluation Agent | B13: 評価提案書作成(自動反映禁止・承認制) | C13: F119, F120, F121 | D13: agents/evaluation.py | E13: 未着手
A14: Pattern Research Agent | B14: パターン発見・定義・更新提案(研究責任者) | C14: F035, F036 | D14: agents/pattern_research.py | E14: 未着手

Sheet Stage_Gate
A1: Stage 昇格ゲート チェックリスト(要件書32章・34章)
A3: Stage移行 | B3: 条件 | C3: 基準 | D3: 判定方法 | E3: 状態
A4: Stage0→1 (Backtest→Replay) | B4: 戦略ロジックが動作する | C4: Backtestで候補抽出/損益計算が回る | D4: simulation/backtest.py 実行 | E4: 未達
A5: Stage1→2 (Replay→Paper Live) | B5: 後知恵バイアス排除検証済 | C5: Replayで当時情報のみで判断できる | D5: simulation/replay.py 実行 | E5: 未達
A6: Stage2→3 (Paper→Semi Auto) | B6: サンプル数 | C6: 20営業日 or 50トレード(過去高速リプレイで短縮可) | D6: promotion_check.py | E6: 未達
B7: 主戦略期待値 | C7: expectancy > 0 | D7: expectancy計算 | E7: 未達
B8: 最大DD | C8: 総資産比 -5% を大きく超えない | D8: DD計算 | E8: 未達
B9: 強制クローズ成功率 | C9: 100% | D9: force_close テスト | E9: 未達
B10: 停止機能 | C10: 日次/週次損失上限・緊急停止正常動作 | D10: 統合テスト | E10: 未達
B11: Optimistic Bias | C11: 許容範囲内 | D11: bias_score.py | E11: 未達
B12: Evaluation Agent確認 | C12: 明確な改善提案が残っていない | D12: Evaluation承認 | E12: 未達
A13: Stage3→4 (Semi→Full Auto) | B13: Semi Auto実績 | C13: 20営業日 or 50実注 | D13: 実注履歴 | E13: 未達
B14: 実約定期待値 | C14: expectancy > 0 (実約定ベース) | D14: 実績集計 | E14: 未達
B15: 平均スリッページ | C15: avg_slippage 許容範囲内 | D15: slippage監視 | E15: 未達
B16: 強制クローズ成功率 | C16: 100% | D16: 実績確認 | E16: 未達
B17: システム稼働率 | C17: broker_uptime/system_uptime 十分 | D17: health監視 | E17: 未達
B18: Evaluation昇格提案 | C18: 昇格推奨が出る | D18: promotion_report.py | E18: 未達
B19: ユーザー承認 | C19: 必ずユーザーが最終承認 | D19: 手動承認 | E19: 未達
A20: 昇格禁止条件(共通) | B20: 期待値マイナス/DD過大/Bias高/クローズ失敗/緊急停止動作不良/主戦略件数不足/執行品質悪化/監督負荷高 | C20: いずれか該当で昇格禁止 | D20: block_rules.py | E20: —

Sheet Roadmap
A1: 運用立ち上げロードマップ (要件書39章)
A3: 期間 | B3: Stage | C3: 実弾 | D3: デイトレリスク | E3: 主要アクション | F3: 完了条件
A4: M-3 〜 M-1 | B4: Stage 0/1/2 | C4: 未投入 | D4: — | E4: Mac mini常時稼働で過去データ高速リプレイ+Paper Live並列実行。パターン爆速蓄積。 | F4: Paper→Semi昇格条件を全てクリア
A5: M=0 (運用初月) | B5: Stage 3 (Semi Auto) | C5: 投入 | D5: 0.2% (半減) | E5: 執行実測データ収集。初月から黒字化目標。 | F5: 執行乖離が想定内・20営業日経過
A6: M+1 | B6: Stage 3 (Semi Auto) | C6: 投入 | D6: 0.3% | E6: リスク枠拡大。Pattern Libraryの浄化開始。 | F6: 継続的な期待値プラス
A7: M+2 | B7: Stage 3 (Semi Auto) | C7: 投入 | D7: 0.4% (要件書通り) | E7: フルリスク運用。期待値安定化。 | F7: Semi→Full昇格条件クリア
A8: M+3 以降 | B8: Stage 4 (部分 Full Auto) | C8: 投入 | D8: 0.4% | E8: デイトレSランクのみFull Auto。スイング・長期はSemi Auto維持。 | F8: —

Sheet Risk_Holes
A1: 要件書で特定された「穴」と対策チェック (穴1〜12)
A3: 穴 | B3: 問題 | C3: 対策(章) | D3: 対応タスクID
A4: 穴1: エッジが弱い | B4: エッジの根拠が曖昧 | C4: 再現性優位で定義 (26章) | D4: F031, F032, F200
A5: 穴2: 約定品質 | B5: 執行品質が悪い | C5: 執行品質ゲート (17章) | D5: F140, F141, F142, F143, F144
A6: 穴3: データソース依存 | B6: 依存先が死ぬと事故 | C6: 縮退運転 (22章) | D6: F106, F107
A7: 穴4: 広げすぎ | B7: 最初の焦点がぼやける | C7: 主戦略集中 (24章) | D7: F200, F201
A8: 穴5: 目標で攻めすぎ | B8: 目標圧力で規律崩壊 | C8: 目標と攻撃性を分離 (27章) | D8: F210, F211
A9: 穴6: 完全放置 | B9: 無監督化で事故 | C9: 監督者付き自律運用 (28章) | D9: F164, F173
A10: 穴7: ラベル曖昧 | B10: 成功/失敗定義が弱い | C10: Success/Failure/Timeout/Invalid 4分類 (29章) | D10: F180, F181, F182, F183
A11: 穴8: 特徴量過多 | B11: 類似局面見つからない/過剰適合 | C11: 初期は最小コアセットに絞る (30章) | D11: F020, F021, F022, F023, F024, F025, F026
A12: 穴9: Pattern Store品質 | B12: 重複・似すぎ・名前違いが増える | C12: 命名規則/統合ルール/バージョン管理 (31章) | D12: F030, F037
A13: 穴10: 本番移行基準 | B13: 昇格基準が曖昧 | C13: 完全版昇格条件 (32章) | D13: F190, F191, F192, F193
A14: 穴11: 運用負荷上限 | B14: 提案/通知/承認が多すぎて疲れる | C14: 通知階層化・承認最小化・初期KPI絞り込み (33章) | D14: F063, F083, F172
A15: 穴12: セクター/銘柄特有性 | B15: パターンが銘柄・セクター個別性を表現できない | C15: sector_filter/symbol_whitelistでパターン絞込み (21章) | D15: F039, F243

Sheet RTM_要件カバレッジ
A1: 要件トレーサビリティマトリクス (RTM) — 要件書 v3.1 全要件とタスクIDの対応
A2: 使い方: E列「タスク紐付け件数」が0の行は赤ハイライト(抜け漏れ)。要件をタスク化するか、理由を記載する。
A4: 要件ID | B4: 章 | C4: 節タイトル | D4: 要件内容 | E4: 対応タスクID | F4: タスク紐付け件数
A5: R-01-01 | B5: 1 | C5: プロダクト名 FIRE | D5: 日本株専門AIエージェントシステム | E5: F005, F006 | F5: =IF(TRIM(E5)="",0,LEN(E5)-LEN(SUBSTITUTE(E5,",",""))+1) -> 2
A6: R-01-02 | B6: 1 | C6: UIテーマ: レトロCRT炎 | D6: ダーク高級路線ではなく昔のブローカー端末風 | E6: F080 | F6: =IF(TRIM(E6)="",0,LEN(E6)-LEN(SUBSTITUTE(E6,",",""))+1) -> 1
A7: R-01-03 | B7: 1 | C7: 最重要目的: 兼業前提の月次年次利益最大化 | D7: LINE通知で発注完結、再現性高く利益最大化 | E7: F062, F070, F071 | F7: =IF(TRIM(E7)="",0,LEN(E7)-LEN(SUBSTITUTE(E7,",",""))+1) -> 3
A8: R-01-04 | B8: 1 | C8: 資産目標: 2年で3000万円 | D8: 目標未達時も無謀なリスク拡大禁止 | E8: F210, F211 | F8: =IF(TRIM(E8)="",0,LEN(E8)-LEN(SUBSTITUTE(E8,",",""))+1) -> 2
A9: R-01-05 | B9: 1 | C9: 乖離率5段階判定(+5%/±5%内/-10%/-20%/再設計) | D9: 日・週・月次で管理 | E9: F118, F210 | F9: =IF(TRIM(E9)="",0,LEN(E9)-LEN(SUBSTITUTE(E9,",",""))+1) -> 2
A10: R-01-06 | B10: 1 | C10: v3.1アップデート: 運用立ち上げロードマップ | D10: M-3〜M+3までのリスク逓増 | E10: F220, F221, F222, F223, F224 | F10: =IF(TRIM(E10)="",0,LEN(E10)-LEN(SUBSTITUTE(E10,",",""))+1) -> 5
A11: R-01-07 | B11: 1 | C11: v3.1: 過去データ高速リプレイ並列実行 | D11: Stage昇格日数短縮 | E11: F045 | F11: =IF(TRIM(E11)="",0,LEN(E11)-LEN(SUBSTITUTE(E11,",",""))+1) -> 1
A12: R-01-08 | B12: 1 | C12: v3.1: Full Auto時 5層防御 | D12: シグナルベース重複防御 | E12: F160, F161, F162, F163, F164 | F12: =IF(TRIM(E12)="",0,LEN(E12)-LEN(SUBSTITUTE(E12,",",""))+1) -> 5
A13: R-01-09 | B13: 1 | C13: v3.1: 執行品質段階的アラート+自己キャリブレーション | D13: 実測値ベース | E13: F144 | F13: =IF(TRIM(E13)="",0,LEN(E13)-LEN(SUBSTITUTE(E13,",",""))+1) -> 1
A14: R-01-10 | B14: 1 | C14: v3.1: 主戦略80%/準戦略20% 優先順位 | D14: M+2までPaper並走 | E14: F200 | F14: =IF(TRIM(E14)="",0,LEN(E14)-LEN(SUBSTITUTE(E14,",",""))+1) -> 1
A15: R-01-11 | B15: 1 | C15: v3.1: ハイブリッド執行方針 | D15: Sランク材料=逆指値→成行、通常=指値主体 | E15: F141 | F15: =IF(TRIM(E15)="",0,LEN(E15)-LEN(SUBSTITUTE(E15,",",""))+1) -> 1
A16: R-01-12 | B16: 1 | C16: v3.1: Paper Live厳しめ約定モデル | D16: +2ティック/値嵩1.5倍/寄り直後1.5倍 | E16: F044, F052 | F16: =IF(TRIM(E16)="",0,LEN(E16)-LEN(SUBSTITUTE(E16,",",""))+1) -> 2
... A18: R-01-14 | B18: 1 | C18: v3.1: 強制クローズ独立プロセス | D18: 別ファイル+Cronフェイルセーフ | E18: F133 | F18: =IF(TRIM(E18)="",0,LEN(E18)-LEN(SUBSTITUTE(E18,",",""))+1) -> 1
A19: R-02-01 | B19: 2 | C19: 日本株専門・兼業投資家 | D19: 現物・信用両方使用 | F19: =IF(TRIM(E19)="",0,LEN(E19)-LEN(SUBSTITUTE(E19,",",""))+1) -> 0
A20: R-02-02 | B20: 2 | C20: デイトレ: 信用取引/値嵩株中心/プライム | D20: 流動性・テーマ性・値動き明確さ | E20: F111 | F20: =IF(TRIM(E20)="",0,LEN(E20)-LEN(SUBSTITUTE(E20,",",""))+1) -> 1
A21: R-02-03 | B21: 2 | C21: スイング: 現物中心/中期トレンド | D21: 波動継続性・RR・PF補完 | E21: F112 | F21: =IF(TRIM(E21)="",0,LEN(E21)-LEN(SUBSTITUTE(E21,",",""))+1) -> 1
A22: R-02-04 | B22: 2 | C22: 長期: 現物/高配当・成長株 | D22: 配当3%以上・営業利益成長3年以上 | E22: F113 | F22: =IF(TRIM(E22)="",0,LEN(E22)-LEN(SUBSTITUTE(E22,",",""))+1) -> 1
A23: R-02-05 | B23: 2 | C23: 長期の増配継続は加点のみ(必須ではない) | E23: F113 | F23: =IF(TRIM(E23)="",0,LEN(E23)-LEN(SUBSTITUTE(E23,",",""))+1) -> 1
A24: R-03-01 | B24: 3 | C24: 主戦略2本柱(レーン1) | D24: 高品質材料初動・主役テーマ連動値嵩株前場初動 | E24: F200 | F24: =IF(TRIM(E24)="",0,LEN(E24)-LEN(SUBSTITUTE(E24,",",""))+1) -> 1
A25: R-03-02 | B25: 3 | C25: 高品質材料の初動 | D25: 好決算/上方修正/増配/自社株買い/進捗/資本政策/受注/提携/政策 | E25: F021, F111 | F25: =IF(TRIM(E25)="",0,LEN(E25)-LEN(SUBSTITUTE(E25,",",""))+1) -> 2
A26: R-03-03 | B26: 3 | C26: 決算シーズンの母集団広・実行候補1-3固定 | D26: 通常より厳しいフィルター | E26: F202 | F26: =IF(TRIM(E26)="",0,LEN(E26)-LEN(SUBSTITUTE(E26,",",""))+1) -> 1
A27: R-03-04 | B27: 3 | C27: 主役テーマ連動の値嵩株前場初動 | D27: 決算期以外の安定頻度確保の本命 | E27: F111, F200 | F27: =IF(TRIM(E27)="",0,LEN(E27)-LEN(SUBSTITUTE(E27,",",""))+1) -> 2
A28: R-03-05 | B28: 3 | C28: 準主戦略(レーン2) | D28: 前日強かった主役押し目再加速/セクター主役続伸初押し/前場ブレイク再試行 | E28: F200 | F28: =IF(TRIM(E28)="",0,LEN(E28)-LEN(SUBSTITUTE(E28,",",""))+1) -> 1
A29: R-04-01 | B29: 4 | C29: Mac mini常駐ランタイム前提 | D29: デイトレとスイングは同一エージェントで扱わない | E29: F012, F013 | F29: =IF(TRIM(E29)="",0,LEN(E29)-LEN(SUBSTITUTE(E29,",",""))+1) -> 2
A30: R-04-02 | B30: 4 | C30: Market Intelligence Agent | D30: 朝の市況・ニュース・セクター分析・朝レポート | E30: F110 | F30: =IF(TRIM(E30)="",0,LEN(E30)-LEN(SUBSTITUTE(E30,",",""))+1) -> 1
A31: R-04-03 | B31: 4 | C31: Daytrade Selection Agent | D31: デイトレ候補抽出・厳選1-3銘柄・スコア | E31: F111 | F31: =IF(TRIM(E31)="",0,LEN(E31)-LEN(SUBSTITUTE(E31,",",""))+1) -> 1
A32: R-04-04 | B32: 4 | C32: Swing Selection Agent | D32: スイング候補抽出・中期トレンド | E32: F112 | F32: =IF(TRIM(E32)="",0,LEN(E32)-LEN(SUBSTITUTE(E32,",",""))+1) -> 1
A33: R-04-05 | B33: 4 | C33: Long-term Selection Agent | D33: 高配当・成長株・長期スコア | E33: F113 | F33: =IF(TRIM(E33)="",0,LEN(E33)-LEN(SUBSTITUTE(E33,",",""))+1) -> 1
A34: R-04-06 | B34: 4 | C34: Portfolio Balance Agent | D34: セクター偏り点検・バランス改善提案 | E34: F114 | F34: =IF(TRIM(E34)="",0,LEN(E34)-LEN(SUBSTITUTE(E34,",",""))+1) -> 1
A35: R-04-07 | B35: 4 | C35: Trade Decision Agent | D35: エントリー/利確/損切/株数/リスク計算/注文案 | E35: F115 | F35: =IF(TRIM(E35)="",0,LEN(E35)-LEN(SUBSTITUTE(E35,",",""))+1) -> 1
... A42: R-05-03 | B42: 5 | C42: デイトレM=0 初月0.2%開始 | D42: リスク係数半減 | E42: F131 | F42: =IF(TRIM(E42)="",0,LEN(E42)-LEN(SUBSTITUTE(E42,",",""))+1) -> 1
A43: R-05-04 | B43: 5 | C43: スイング通常0.6%/強気0.8%上限 | E43: F130 | F43: =IF(TRIM(E43)="",0,LEN(E43)-LEN(SUBSTITUTE(E43,",",""))+1) -> 1
A44: R-05-05 | B44: 5 | C44: スイングM=0 初月0.3%開始 | D44: リスク係数半減 | E44: F131 | F44: =IF(TRIM(E44)="",0,LEN(E44)-LEN(SUBSTITUTE(E44,",",""))+1) -> 1
A45: R-05-06 | B45: 5 | C45: 長期1銘柄最大1.2%(分割買い前提) | E45: F130 | F45: =IF(TRIM(E45)="",0,LEN(E45)-LEN(SUBSTITUTE(E45,",",""))+1) -> 1
A46: R-05-07 | B46: 5 | C46: ロット計算式 floor(許容損失÷(ENTRY-STOP)) | D46: 100株単位丸め | E46: F115, F130 | F46: =IF(TRIM(E46)="",0,LEN(E46)-LEN(SUBSTITUTE(E46,",",""))+1) -> 2
A47: R-05-08 | B47: 5 | C47: 日次-1.2%新規停止/-1.8%当日終了 | E47: F132 | F47: =IF(TRIM(E47)="",0,LEN(E47)-LEN(SUBSTITUTE(E47,",",""))+1) -> 1
A48: R-05-09 | B48: 5 | C48: 週次-3.0%守備/-4.0%大幅制限/-5.0%原則停止 | E48: F132 | F48: =IF(TRIM(E48)="",0,LEN(E48)-LEN(SUBSTITUTE(E48,",",""))+1) -> 1
...

Sheet RTM_章別サマリー
A1: 章別 要件カバレッジサマリー
A2: 要件書の各章で、要件が何件ありタスクに落ちているかを集計。未カバーが1件でもあれば要対応。
A4: 章 | B4: 章タイトル | C4: 要件数 | D4: カバー済 | E4: 未カバー | F4: カバレッジ率
A5: 1 | B5: プロジェクト概要と最重要目的 | C5: =COUNTIF(RTM_要件カバレッジ!B5:B332,A5) -> 14 | D5: =SUMPRODUCT((RTM_要件カバレッジ!B5:B332=A5)*(RTM_要件カバレッジ!F5:F332>=1)) -> 14 | E5: =C5-D5 -> 0 | F5: =IFERROR(D5/C5,0) -> 1
A6: 2 | B6: ユーザープロファイルと投資対象 | C6: =COUNTIF(RTM_要件カバレッジ!B5:B332,A6) -> 5 | D6: =SUMPRODUCT((RTM_要件カバレッジ!B5:B332=A6)*(RTM_要件カバレッジ!F5:F332>=1)) -> 4 | E6: =C6-D6 -> 1 | F6: =IFERROR(D6/C6,0) -> 0.8
A7: 3 | B7: FIREの主戦略(第一エッジ) | C7: =COUNTIF(RTM_要件カバレッジ!B5:B332,A7) -> 5 | D7: =SUMPRODUCT((RTM_要件カバレッジ!B5:B332=A7)*(RTM_要件カバレッジ!F5:F332>=1)) -> 5 | E7: =C7-D7 -> 0 | F7: =IFERROR(D7/C7,0) -> 1
A8: 4 | B8: システム構成(エージェント群) | C8: =COUNTIF(RTM_要件カバレッジ!B5:B332,A8) -> 11 | D8: =SUMPRODUCT((RTM_要件カバレッジ!B5:B332=A8)*(RTM_要件カバレッジ!F5:F332>=1)) -> 11 | E8: =C8-D8 -> 0 | F8: =IFERROR(D8/C8,0) -> 1
A9: 5 | B9: 許容損失とリスク管理(準攻撃型) | C9: =COUNTIF(RTM_要件カバレッジ!B5:B332,A9) -> 14 | D9: =SUMPRODUCT((RTM_要件カバレッジ!B5:B332=A9)*(RTM_要件カバレッジ!F5:F332>=1)) -> 14 | E9: =C9-D9 -> 0 | F9: =IFERROR(D9/C9,0) -> 1
A10: 6 | B10: LINE通知設計(注文完成形) | C10: =COUNTIF(RTM_要件カバレッジ!B5:B332,A10) -> 10 | D10: =SUMPRODUCT((RTM_要件カバレッジ!B5:B332=A10)*(RTM_要件カバレッジ!F5:F332>=1)) -> 10 | E10: =C10-D10 -> 0 | F10: =IFERROR(D10/C10,0) -> 1
A11: 7 | B11: 候補銘柄の抽出ルール | C11: =COUNTIF(RTM_要件カバレッジ!B5:B332,A11) -> 4 | D11: =SUMPRODUCT((RTM_要件カバレッジ!B5:B332=A11)*(RTM_要件カバレッジ!F5:F332>=1)) -> 4 | E11: =C11-D11 -> 0 | F11: =IFERROR(D11/C11,0) -> 1
A12: 8 | B12: 運用スケジュール(時間帯別ルール) | C12: =COUNTIF(RTM_要件カバレッジ!B5:B332,A12) -> 15 | D12: =SUMPRODUCT((RTM_要件カバレッジ!B5:B332=A12)*(RTM_要件カバレッジ!F5:F332>=1)) -> 15 | E12: =C12-D12 -> 0 | F12: =IFERROR(D12/C12,0) -> 1
A13: 10 | B13: スコアリングシステムと特徴量 | C13: =COUNTIF(RTM_要件カバレッジ!B5:B332,A13) -> 5 | D13: =SUMPRODUCT((RTM_要件カバレッジ!B5:B332=A13)*(RTM_要件カバレッジ!F5:F332>=1)) -> 5 | E13: =C13-D13 -> 0 | F13: =IFERROR(D13/C13,0) -> 1
A14: 11 | B14: Pattern Store と再現性エンジン | C14: =COUNTIF(RTM_要件カバレッジ!B5:B332,A14) -> 7 | D14: =SUMPRODUCT((RTM_要件カバレッジ!B5:B332=A14)*(RTM_要件カバレッジ!F5:F332>=1)) -> 7 | E14: =C14-D14 -> 0 | F14: =IFERROR(D14/C14,0) -> 1
A15: 12 | B15: 全自動運用モードと移行ステップ | C15: =COUNTIF(RTM_要件カバレッジ!B5:B332,A15) -> 19 | D15: =SUMPRODUCT((RTM_要件カバレッジ!B5:B332=A15)*(RTM_要件カバレッジ!F5:F332>=1)) -> 19 | E15: =C15-D15 -> 0 | F15: =IFERROR(D15/C15,0) -> 1
A16: 13 | B16: Evaluation Agent と Dashboard | C16: =COUNTIF(RTM_要件カバレッジ!B5:B332,A16) -> 19 | D16: =SUMPRODUCT((RTM_要件カバレッジ!B5:B332=A16)*(RTM_要件カバレッジ!F5:F332>=1)) -> 19 | E16: =C16-D16 -> 0 | F16: =IFERROR(D16/C16,0) -> 1
A17: 14 | B17: データソース優先順位と縮退運転 | C17: =COUNTIF(RTM_要件カバレッジ!B5:B332,A17) -> 6 | D17: =SUMPRODUCT((RTM_要件カバレッジ!B5:B332=A17)*(RTM_要件カバレッジ!F5:F332>=1)) -> 6 | E17: =C17-D17 -> 0 | F17: =IFERROR(D17/C17,0) -> 1
A18: 15 | B18: Claude Code実装に向けた次のステップ | C18: =COUNTIF(RTM_要件カバレッジ!B5:B332,A18) -> 6 | D18: =SUMPRODUCT((RTM_要件カバレッジ!B5:B332=A18)*(RTM_要件カバレッジ!F5:F332>=1)) -> 6 | E18: =C18-D18 -> 0 | F18: =IFERROR(D18/C18,0) -> 1
A19: 16 | B19: Mac miniセットアップ | C19: =COUNTIF(RTM_要件カバレッジ!B5:B332,A19) -> 10 | D19: =SUMPRODUCT((RTM_要件カバレッジ!B5:B332=A19)*(RTM_要件カバレッジ!F5:F332>=1)) -> 10 | E19: =C19-D19 -> 0 | F19: =IFERROR(D19/C19,0) -> 1
A20: 17 | B20: 執行品質設計(穴2対策) | C20: =COUNTIF(RTM_要件カバレッジ!B5:B332,A20) -> 11 | D20: =SUMPRODUCT((RTM_要件カバレッジ!B5:B332=A20)*(RTM_要件カバレッジ!F5:F332>=1)) -> 11 | E20: =C20-D20 -> 0 | F20: =IFERROR(D20/C20,0) -> 1
A21: 18 | B21: 時間軸戦略方針 | C21: =COUNTIF(RTM_要件カバレッジ!B5:B332,A21) -> 8 | D21: =SUMPRODUCT((RTM_要件カバレッジ!B5:B332=A21)*(RTM_要件カバレッジ!F5:F332>=1)) -> 8 | E21: =C21-D21 -> 0 | F21: =IFERROR(D21/C21,0) -> 1
A22: 19 | B22: Simulation / Paper Live 方針 | C22: =COUNTIF(RTM_要件カバレッジ!B5:B332,A22) -> 10 | D22: =SUMPRODUCT((RTM_要件カバレッジ!B5:B332=A22)*(RTM_要件カバレッジ!F5:F332>=1)) -> 10 | E22: =C22-D22 -> 0 | F22: =IFERROR(D22/C22,0) -> 1
A23: 20 | B23: FIREの勝率優位性の根拠 | C23: =COUNTIF(RTM_要件カバレッジ!B5:B332,A23) -> 6 | D23: =SUMPRODUCT((RTM_要件カバレッジ!B5:B332=A23)*(RTM_要件カバレッジ!F5:F332>=1)) -> 6 | E23: =C23-D23 -> 0 | F23: =IFERROR(D23/C23,0) -> 1
A24: 21 | B24: Pattern Research Agent / Pattern Store詳細 | C24: =COUNTIF(RTM_要件カバレッジ!B5:B332,A24) -> 14 | D24: =SUMPRODUCT((RTM_要件カバレッジ!B5:B332=A24)*(RTM_要件カバレッジ!F5:F332>=1)) -> 14 | E24: =C24-D24 -> 0 | F24: =IFERROR(D24/C24,0) -> 1
A25: 22 | B25: データソース依存と縮退運転設計(穴3) | C25: =COUNTIF(RTM_要件カバレッジ!B5:B332,A25) -> 10 | D25: =SUMPRODUCT((RTM_要件カバレッジ!B5:B332=A25)*(RTM_要件カバレッジ!F5:F332>=1)) -> 10 | E25: =C25-D25 -> 0 | F25: =IFERROR(D25/C25,0) -> 1
A26: 23 | B26: FIRE Runtime / 常駐基盤 | C26: =COUNTIF(RTM_要件カバレッジ!B5:B332,A26) -> 6 | D26: =SUMPRODUCT((RTM_要件カバレッジ!B5:B332=A26)*(RTM_要件カバレッジ!F5:F332>=1)) -> 6 | E26: =C26-D26 -> 0 | F26: =IFERROR(D26/C26,0) -> 1
A27: 24 | B27: 機能の絞り込みと監視階層(穴4) | C27: =COUNTIF(RTM_要件カバレッジ!B5:B332,A27) -> 8 | D27: =SUMPRODUCT((RTM_要件カバレッジ!B5:B332=A27)*(RTM_要件カバレッジ!F5:F332>=1)) -> 8 | E27: =C27-D27 -> 0 | F27: =IFERROR(D27/C27,0) -> 1
A28: 25 | B28: 戦略階層と頻度設計 | C28: =COUNTIF(RTM_要件カバレッジ!B5:B332,A28) -> 7 | D28: =SUMPRODUCT((RTM_要件カバレッジ!B5:B332=A28)*(RTM_要件カバレッジ!F5:F332>=1)) -> 7 | E28: =C28-D28 -> 0 | F28: =IFERROR(D28/C28,0) -> 1
A29: 26 | B29: FIREのエッジ定義 | C29: =COUNTIF(RTM_要件カバレッジ!B5:B332,A29) -> 9 | D29: =SUMPRODUCT((RTM_要件カバレッジ!B5:B332=A29)*(RTM_要件カバレッジ!F5:F332>=1)) -> 9 | E29: =C29-D29 -> 0 | F29: =IFERROR(D29/C29,0) -> 1
A30: 27 | B30: 目標圧力と運用規律の分離(穴5) | C30: =COUNTIF(RTM_要件カバレッジ!B5:B332,A30) -> 7 | D30: =SUMPRODUCT((RTM_要件カバレッジ!B5:B332=A30)*(RTM_要件カバレッジ!F5:F332>=1)) -> 7 | E30: =C30-D30 -> 0 | F30: =IFERROR(D30/C30,0) -> 1
A31: 28 | B31: 監督者付き自律運用システム(穴6) | C31: =COUNTIF(RTM_要件カバレッジ!B5:B332,A31) -> 9 | D31: =SUMPRODUCT((RTM_要件カバレッジ!B5:B332=A31)*(RTM_要件カバレッジ!F5:F332>=1)) -> 9 | E31: =C31-D31 -> 0 | F31: =IFERROR(D31/C31,0) -> 1
A32: 29 | B32: 成功/失敗ラベル定義(穴7) | C32: =COUNTIF(RTM_要件カバレッジ!B5:B332,A32) -> 11 | D32: =SUMPRODUCT((RTM_要件カバレッジ!B5:B332=A32)*(RTM_要件カバレッジ!F5:F332>=1)) -> 11 | E32: =C32-D32 -> 0 | F32: =IFERROR(D32/C32,0) -> 1
A33: 30 | B33: 特徴量の初期絞り込み(穴8) | C33: =COUNTIF(RTM_要件カバレッジ!B5:B332,A33) -> 2 | D33: =SUMPRODUCT((RTM_要件カバレッジ!B5:B332=A33)*(RTM_要件カバレッジ!F5:F332>=1)) -> 2 | E33: =C33-D33 -> 0 | F33: =IFERROR(D33/C33,0) -> 1
A34: 31 | B34: Pattern Storeの品質管理(穴9) | C34: =COUNTIF(RTM_要件カバレッジ!B5:B332,A34) -> 6 | D34: =SUMPRODUCT((RTM_要件カバレッジ!B5:B332=A34)*(RTM_要件カバレッジ!F5:F332>=1)) -> 6 | E34: =C34-D34 -> 0 | F34: =IFERROR(D34/C34,0) -> 1
A35: 32 | B35: 本番移行基準の厳密化(穴10) | C35: =COUNTIF(RTM_要件カバレッジ!B5:B332,A35) -> 3 | D35: =SUMPRODUCT((RTM_要件カバレッジ!B5:B332=A35)*(RTM_要件カバレッジ!F5:F332>=1)) -> 3 | E35: =C35-D35 -> 0 | F35: =IFERROR(D35/C35,0) -> 1
A36: 33 | B36: 人間の運用負荷の上限設計(穴11) | C36: =COUNTIF(RTM_要件カバレッジ!B5:B332,A36) -> 4 | D36: =SUMPRODUCT((RTM_要件カバレッジ!B5:B332=A36)*(RTM_要件カバレッジ!F5:F332>=1)) -> 4 | E36: =C36-D36 -> 0 | F36: =IFERROR(D36/C36,0) -> 1
A37: 34 | B37: 本番移行基準の詳細 | C37: =COUNTIF(RTM_要件カバレッジ!B5:B332,A37) -> 6 | D37: =SUMPRODUCT((RTM_要件カバレッジ!B5:B332=A37)*(RTM_要件カバレッジ!F5:F332>=1)) -> 6 | E37: =C37-D37 -> 0 | F37: =IFERROR(D37/C37,0) -> 1
A38: 35 | B38: Mac mini 常駐基盤時間帯別分担 | C38: =COUNTIF(RTM_要件カバレッジ!B5:B332,A38) -> 4 | D38: =SUMPRODUCT((RTM_要件カバレッジ!B5:B332=A38)*(RTM_要件カバレッジ!F5:F332>=1)) -> 4 | E38: =C38-D38 -> 0 | F38: =IFERROR(D38/C38,0) -> 1
A39: 36 | B39: 初期特徴量セットの詳細定義 | C39: =COUNTIF(RTM_要件カバレッジ!B5:B332,A39) -> 10 | D39: =SUMPRODUCT((RTM_要件カバレッジ!B5:B332=A39)*(RTM_要件カバレッジ!F5:F332>=1)) -> 10 | E39: =C39-D39 -> 0 | F39: =IFERROR(D39/C39,0) -> 1
A40: 37 | B40: Pattern Store 4階層構造 | C40: =COUNTIF(RTM_要件カバレッジ!B5:B332,A40) -> 12 | D40: =SUMPRODUCT((RTM_要件カバレッジ!B5:B332=A40)*(RTM_要件カバレッジ!F5:F332>=1)) -> 12 | E40: =C40-D40 -> 0 | F40: =IFERROR(D40/C40,0) -> 1
A41: 38 | B41: 運用モード/休止/旅行モード | C41: =COUNTIF(RTM_要件カバレッジ!B5:B332,A41) -> 10 | D41: =SUMPRODUCT((RTM_要件カバレッジ!B5:B332=A41)*(RTM_要件カバレッジ!F5:F332>=1)) -> 10 | E41: =C41-D41 -> 0 | F41: =IFERROR(D41/C41,0) -> 1
...
